<?xml version="1.0" ?>
<!-- =================================================================================== -->
<!-- |    This document was autogenerated by xacro from exhx5.urdf.xacro               | -->
<!-- |    EDITING THIS FILE BY HAND IS NOT RECOMMENDED                                 | -->
<!-- =================================================================================== -->
<!-- This URDF was automatically created by SolidWorks to URDF Exporter! Originally created by Stephen Brawner (brawner@gmail.com) 
     Commit Version: 1.5.0-0-g9aa0fdb  Build Version: 1.5.7004.21443
     For more information, please see http://wiki.ros.org/sw_urdf_exporter -->
<robot name="exhx5" xmlns:xacro="http://ros.org/wiki/xacro">
  <gazebo>
    <plugin filename="libgazebo_ros_control.so" name="gazebo_ros_control">
      <robotNamespace>/exhx5</robotNamespace>
      <robotSimType>gazebo_ros_control/DefaultRobotHWSim</robotSimType>
      <legacyModeNS>true</legacyModeNS>
    </plugin>
  </gazebo>
  <!-- body link -->
  <gazebo reference="MP_BODY">
    <mu1>0.2</mu1>
    <mu2>0.2</mu2>
    <material>Gazebo/White</material>
    <selfCollide>false</selfCollide>
  </gazebo>
  <!-- left leg links -->
  <gazebo reference="MP_PELVIS_L">
    <mu1>0.2</mu1>
    <mu2>0.2</mu2>
    <material>Gazebo/White</material>
    <selfCollide>false</selfCollide>
  </gazebo>
  <gazebo reference="MP_THIGH1_L">
    <mu1>0.2</mu1>
    <mu2>0.2</mu2>
    <material>Gazebo/White</material>
    <selfCollide>false</selfCollide>
  </gazebo>
  <gazebo reference="MP_THIGH2_L">
    <mu1>0.2</mu1>
    <mu2>0.2</mu2>
    <material>Gazebo/White</material>
    <selfCollide>false</selfCollide>
  </gazebo>
  <gazebo reference="MP_TIBIA_L">
    <mu1>0.2</mu1>
    <mu2>0.2</mu2>
    <material>Gazebo/White</material>
    <selfCollide>false</selfCollide>
  </gazebo>
  <gazebo reference="MP_ANKLE1_L">
    <mu1>0.2</mu1>
    <mu2>0.2</mu2>
    <material>Gazebo/White</material>
    <selfCollide>false</selfCollide>
  </gazebo>
  <gazebo reference="MP_ANKLE2_L">
    <kp>1000000.0</kp>
    <kd>10.0</kd>
    <mu1>9000</mu1>
    <mu2>9000</mu2>
    <!--<fdir1>1 0 0</fdir1>-->
    <maxVel>1.0</maxVel>
    <minDepth>0.001</minDepth>
    <material>Gazebo/White</material>
  </gazebo>
  <!-- right leg links -->
  <gazebo reference="MP_PELVIS_R">
    <mu1>0.2</mu1>
    <mu2>0.2</mu2>
    <material>Gazebo/White</material>
    <selfCollide>false</selfCollide>
  </gazebo>
  <gazebo reference="MP_THIGH1_R">
    <mu1>0.2</mu1>
    <mu2>0.2</mu2>
    <material>Gazebo/White</material>
    <selfCollide>false</selfCollide>
  </gazebo>
  <gazebo reference="MP_THIGH2_R">
    <mu1>0.2</mu1>
    <mu2>0.2</mu2>
    <material>Gazebo/White</material>
    <selfCollide>false</selfCollide>
  </gazebo>
  <gazebo reference="MP_TIBIA_R">
    <mu1>0.2</mu1>
    <mu2>0.2</mu2>
    <material>Gazebo/White</material>
    <selfCollide>false</selfCollide>
  </gazebo>
  <gazebo reference="MP_ANKLE1_R">
    <mu1>0.2</mu1>
    <mu2>0.2</mu2>
    <material>Gazebo/White</material>
    <selfCollide>false</selfCollide>
  </gazebo>
  <gazebo reference="MP_ANKLE2_R">
    <kp>1000000.0</kp>
    <kd>10.0</kd>
    <mu1>9000</mu1>
    <mu2>9000</mu2>
    <!--<fdir1>1 0 0</fdir1>-->
    <maxVel>1.0</maxVel>
    <minDepth>0.001</minDepth> 
    <material>Gazebo/White</material>
  </gazebo>
  <!--upper body-->
  <gazebo reference="MP_HEAD">
    <mu1>0.2</mu1>
    <mu2>0.2</mu2>
    <material>Gazebo/White</material>
    <selfCollide>false</selfCollide>
  </gazebo>
  <gazebo reference="MP_NECK">
    <mu1>0.2</mu1>
    <mu2>0.2</mu2>
    <material>Gazebo/White</material>
    <selfCollide>false</selfCollide>
  </gazebo>
  <gazebo reference="MP_PMDCAMBOARD">
    <mu1>0.2</mu1>
    <mu2>0.2</mu2>
    <material>Gazebo/White</material>
    <selfCollide>false</selfCollide>
  </gazebo>

  <!--<link name="world">
  </link>
  <joint name="fixed" type="fixed">
    <parent link="world"/>
    <child link="Base"/>
  </joint>-->
 
  <link name="base_link">
  </link>
  <joint name="base_link_to_body" type="fixed">
    <parent link="base_link"/>
    <child link="MP_BODY"/>
  </joint>

  <link name="MP_BODY">

    <inertial>
      <origin xyz="-0.003053 -0.038651 -0.019268" />
      <mass value="0.97559947"/>
      <inertia ixx="3.1081800"  ixy="-0.25460189"  ixz="2.0318174" iyy="6.3787776" iyz="0.16417863" izz="5.3316425" />
    </inertial>
    
    <visual>
      <origin rpy="0 0 0" xyz="0 0 0"/>
      <geometry>
        <mesh filename="package://exhx5_description/meshes/body_link.STL"/>
      </geometry>
      <material name="">
        <color rgba="0.79216 0.81961 0.93333 1"/>
      </material>
    </visual>
    <collision>
      <origin rpy="0 0 0" xyz="0 0 0"/>
      <geometry>
        <mesh filename="package://exhx5_description/meshes/body_link.STL"/>
      </geometry>
    </collision>
  </link>
  <link name="MP_PELVIS_R">
    <inertial>
      <origin xyz="0.000000 0.000480 0.018437" />
      <mass value="0.197"/>
      <inertia ixx="0.12259691"  ixy="0.00071127469"  ixz="0.00081143913" iyx="0.00071127469" iyy="0.11066637" iyz="-0.0071635476" izx="0.00081143913" izy="-0.0071635476" izz="0.041877668" />
    </inertial>
    <visual>
      <origin rpy="0 0 0" xyz="0 0 0"/>
      <geometry>
        <mesh filename="package://exhx5_description/meshes/r_hip_yaw_link.STL"/>
      </geometry>
      <material name="">
        <color rgba="0.79216 0.81961 0.93333 1"/>
      </material>
    </visual>
    <collision>
      <origin rpy="0 0 0" xyz="0 0 0"/>
      <geometry>
        <mesh filename="package://exhx5_description/meshes/r_hip_yaw_link.STL"/>
      </geometry>
    </collision>
  </link>
  <joint name="j_pelvis_r" type="revolute">
    <origin rpy="0 0 1.57079632679488" xyz="0 -0.0539999999999998 -0.024500000000006"/>
    <parent link="MP_BODY"/>
    <child link="MP_PELVIS_R"/>
    <axis xyz="0 0 -1"/>
        <limit effort="1000" velocity="100" lower="-3.14" upper="3.14" /> 
     
  </joint>
  <link name="MP_THIGH1_R">
    <inertial>
      <origin xyz="0.000079 -0.018242 0.0138735" />
      <mass value="0.11904336"/>
      <inertia ixx="0.097950272"  ixy="0.0012119368"  ixz="-0.00021223016" iyx="0.00122119368" iyy="0.032848287" iyz="-0.0019474021" izx="-0.00021223016" izy="-0.0019474021" izz="0.11493509" />
    </inertial>
    <visual>
      <origin rpy="0 0 0" xyz="0 0 0"/>
      <geometry>
        <mesh filename="package://exhx5_description/meshes/r_hip_roll_link.STL"/>
      </geometry>
      <material name="">
        <color rgba="0.79216 0.81961 0.93333 1"/>
      </material>
    </visual>
    <collision>
      <origin rpy="0 0 0" xyz="0 0 0"/>
      <geometry>
        <mesh filename="package://exhx5_description/meshes/r_hip_roll_link.STL"/>
      </geometry>
    </collision>
  </link>
  <joint name="j_thigh1_r" type="revolute">
    <origin rpy="1.5708 1.5708 0" xyz="0 0 0"/>
    <parent link="MP_PELVIS_R"/>
    <child link="MP_THIGH1_R"/>
    <axis xyz="0 0 1"/>
        <limit effort="1000" velocity="100" lower="-3.14" upper="3.14" /> 
     
  </joint>
  <link name="MP_THIGH2_R">
    <inertial>
      <origin xyz="0.062965 -0.000323 0.000692" />
      <mass value="0.11904336"/>
      <inertia ixx="0.097950272"  ixy="0.0012119368"  ixz="-0.00021223016" iyx="0.00122119368" iyy="0.032848287" iyz="-0.0019474021" izx="-0.00021223016" izy="-0.0019474021" izz="0.11493509" />
    </inertial>
    <visual>
      <origin rpy="0 0 0" xyz="0 0 0"/>
      <geometry>
        <mesh filename="package://exhx5_description/meshes/r_hip_pitch_link.STL"/>
      </geometry>
      <material name="">
        <color rgba="0.79216 0.81961 0.93333 1"/>
      </material>
    </visual>
    <collision>
      <origin rpy="0 0 0" xyz="0 0 0"/>
      <geometry>
        <mesh filename="package://exhx5_description/meshes/r_hip_pitch_link.STL"/>
      </geometry>
    </collision>
  </link>
  <joint name="j_thigh2_r" type="revolute">
    <origin rpy="1.5708 0 0" xyz="0 0 0"/>
    <parent link="MP_THIGH1_R"/>
    <child link="MP_THIGH2_R"/>
    <axis xyz="0 0 -1"/>
    <limit effort="1000" velocity="100" lower="-3.14" upper="3.14" /> 
     
  </joint>
  <link name="MP_TIBIA_R">
    <inertial>
      <origin xyz="0.053955 0.006548 -0.000592" />
      <mass value="0.070309794"/>
      <inertia ixx="0.093369608"  ixy="-0.00093567395"  ixz="-0.00023992085" iyx="-0.00093567395" iyy="0.046295534" iyz="-0.012858493" izx="-0.00023992085" izy="-0.012858493" izz="0.11351516" />
    </inertial>
    <visual>
      <origin rpy="0 0 0" xyz="0 0 0"/>
      <geometry>
        <mesh filename="package://exhx5_description/meshes/r_knee_link.STL"/>
      </geometry>
      <material name="">
        <color rgba="0.79216 0.81961 0.93333 1"/>
      </material>
    </visual>
    <collision>
      <origin rpy="0 0 0" xyz="0 0 0"/>
      <geometry>
        <mesh filename="package://exhx5_description/meshes/r_knee_link.STL"/>
      </geometry>
    </collision>
  </link>
  <joint name="j_tibia_r" type="revolute">
    <origin rpy="0 0.0004216 0.42593" xyz="0.075954 0 0"/>
    <parent link="MP_THIGH2_R"/>
    <child link="MP_TIBIA_R"/>
    <axis xyz="-0.0004216 0 -1"/>
    <limit effort="1000" velocity="100" lower="-3.14" upper="3.14" /> 
     
  </joint>
  <link name="MP_ANKLE1_R">
    <inertial>
      <origin xyz="-0.000214 -0.018536 -0.013873" />
      <mass value="0.16710792"/>
      <inertia ixx="0.12079175"  ixy="-0.00079781067"  ixz="-0.00039322246" iyx="-0.00079781067" iyy="0.10885465" iyz="0.0070770117" izx="-0.00039322246" izy="0.0070770117" izz="0.041871103" />
    </inertial>
    <visual>
      <origin rpy="0 0 0" xyz="0 0 0"/>
      <geometry>
        <mesh filename="package://exhx5_description/meshes/r_ank_pitch_link.STL"/>
      </geometry>
      <material name="">
        <color rgba="0.79216 0.81961 0.93333 1"/>
      </material>
    </visual>
    <collision>
      <origin rpy="0 0 0" xyz="0 0 0"/>
      <geometry>
        <mesh filename="package://exhx5_description/meshes/r_ank_pitch_link.STL"/>
      </geometry>
    </collision>
  </link>

  <!-- change the axis from <axis xyz="0 0 1"/>/-->  
  <joint name="j_ankle1_r" type="revolute">
    <origin rpy="0.00017419 -0.00038393 -0.42593" xyz="0.059298 0 0"/>
    <parent link="MP_TIBIA_R"/>
    <child link="MP_ANKLE1_R"/>
    <axis xyz="0 0 1"/>
    <limit effort="1000" velocity="100" lower="-3.14" upper="3.14" /> 
     
  </joint>
  
  <link name="MP_ANKLE2_R">
    <inertial>
      <origin rpy="0 0 0" xyz="0.00474 -0.010189 0.017732"/>
      <mass value="0.1244"/>
      <inertia ixx="0.00013147" ixy="1.1537E-08" ixz="1.5896E-06" iyy="9.5366E-05" iyz="-2.4562E-07" izz="4.9024E-05"/>
    </inertial>
    <visual>
      <origin rpy="0 0 0" xyz="0 0 0"/>
      <geometry>
        <mesh filename="package://exhx5_description/meshes/r_ank_roll_link.STL"/>
      </geometry>
      <material name="">
        <color rgba="0.79216 0.81961 0.93333 1"/>
      </material>
    </visual>
    <collision>
      <origin rpy="0 0 0" xyz="0 0 0"/>
      <geometry>
        <mesh filename="package://exhx5_description/meshes/r_ank_roll_link.STL"/>
      </geometry>
    </collision>
  </link>
  <joint name="j_ankle2_r" type="revolute">
    <origin rpy="-1.5708 0 0" xyz="0.0465 0 0"/>
    <parent link="MP_ANKLE1_R"/>
    <child link="MP_ANKLE2_R"/>
    <axis xyz="0 0 -1"/>
    <limit effort="1000" velocity="100" lower="-3.14" upper="3.14" /> 
     
  </joint>
  <link name="MP_PELVIS_L">
    <inertial>
      <origin xyz="0.000000 0.000480 0.018437" />
      <mass value="0.167"/>
      <inertia ixx="0.12259691"  ixy="0.00071127469"  ixz="0.00081143913" iyx="0.00071127469" iyy="0.11066637" iyz="-0.0071635476" izx="0.00081143913" izy="-0.0071635476" izz="0.041877668" />
    </inertial>
    <visual>
      <origin rpy="0 0 0" xyz="0 0 0"/>
      <geometry>
        <mesh filename="package://exhx5_description/meshes/l_hip_yaw_link.STL"/>
      </geometry>
      <material name="">
        <color rgba="0.79216 0.81961 0.93333 1"/>
      </material>
    </visual>
    <collision>
      <origin rpy="0 0 0" xyz="0 0 0"/>
      <geometry>
        <mesh filename="package://exhx5_description/meshes/l_hip_yaw_link.STL"/>
      </geometry>
    </collision>
  </link>
  <joint name="j_pelvis_l" type="revolute">
    <origin rpy="0 0 1.5708" xyz="0 0.054 -0.0245"/>
    <parent link="MP_BODY"/>
    <child link="MP_PELVIS_L"/>
    <axis xyz="-2.8454E-05 0 -1"/>
    <limit effort="1000" velocity="100" lower="-3.14" upper="3.14" /> 
     
  </joint>
  <link name="MP_THIGH1_L">
    <inertial>
      <origin xyz="0.000079 0.018242 0.013873" />
      <mass value="0.11904336"/>
      <inertia ixx="0.097950272"  ixy="0.0012119368"  ixz="-0.00021223016" iyx="0.00122119368" iyy="0.032848287" iyz="-0.0019474021" izx="-0.00021223016" izy="-0.0019474021" izz="0.11493509" />
    </inertial>
    <visual>
      <origin rpy="0 0 0" xyz="0 0 0"/>
      <geometry>
        <mesh filename="package://exhx5_description/meshes/l_hip_roll_link.STL"/>
      </geometry>
      <material name="">
        <color rgba="0.79216 0.81961 0.93333 1"/>
      </material>
    </visual>
    <collision>
      <origin rpy="0 0 0" xyz="0 0 0"/>
      <geometry>
        <mesh filename="package://exhx5_description/meshes/l_hip_roll_link.STL"/>
      </geometry>
    </collision>
  </link>
  <joint name="j_thigh1_l" type="revolute">
    <origin rpy="1.5708 1.5708 0" xyz="0 0 0"/>
    <parent link="MP_PELVIS_L"/>
    <child link="MP_THIGH1_L"/>
    <axis xyz="0 0 -1"/>
    <limit effort="1000" velocity="100" lower="-3.14" upper="3.14" /> 
     
  </joint>
  <link name="MP_THIGH2_L">
    <inertial>
      <origin xyz="-0.062965 -0.000323 0.000692" />
      <mass value="0.11904336"/>
      <inertia ixx="0.097950272"  ixy="0.0012119368"  ixz="-0.00021223016" iyx="0.00122119368" iyy="0.032848287" iyz="-0.0019474021" izx="-0.00021223016" izy="-0.0019474021" izz="0.11493509" />
    </inertial>
    <visual>
      <origin rpy="0 0 0" xyz="0 0 0"/>
      <geometry>
        <mesh filename="package://exhx5_description/meshes/l_hip_pitch_link.STL"/>
      </geometry>
      <material name="">
        <color rgba="0.79216 0.81961 0.93333 1"/>
      </material>
    </visual>
    <collision>
      <origin rpy="0 0 0" xyz="0 0 0"/>
      <geometry>
        <mesh filename="package://exhx5_description/meshes/l_hip_pitch_link.STL"/>
      </geometry>
    </collision>
  </link>
  <joint name="j_thigh2_l" type="revolute">
    <origin rpy="1.5708 0 0" xyz="0 0 0"/>
    <parent link="MP_THIGH1_L"/>
    <child link="MP_THIGH2_L"/>
    <axis xyz="0 0 1"/>
    <limit effort="1000" velocity="100" lower="-3.14" upper="3.14" /> 
     
  </joint>
  <link name="MP_TIBIA_L">
    <inertial>
      <origin xyz="-0.053955 0.006548 -0.000592" />
      <mass value="0.070309794"/>
      <inertia ixx="0.093369608"  ixy="-0.00093567395"  ixz="-0.00023992085" iyx="-0.00093567395" iyy="0.046295534" iyz="-0.012858493" izx="-0.00023992085" izy="-0.012858493" izz="0.11351516" />
    </inertial>
    <visual>
      <origin rpy="0 0 0" xyz="0 0 0"/>
      <geometry>
        <mesh filename="package://exhx5_description/meshes/l_knee_link.STL"/>
      </geometry>
      <material name="">
        <color rgba="0.79216 0.81961 0.93333 1"/>
      </material>
    </visual>
    <collision>
      <origin rpy="0 0 0" xyz="0 0 0"/>
      <geometry>
        <mesh filename="package://exhx5_description/meshes/l_knee_link.STL"/>
      </geometry>
    </collision>
  </link>
  <joint name="j_tibia_l" type="revolute">
    <origin rpy="0 0.0025296 0.42593" xyz="0.075954 0 0"/>
    <parent link="MP_THIGH2_L"/>
    <child link="MP_TIBIA_L"/>
    <axis xyz="0.0025296 0 1"/>
    <limit effort="1000" velocity="100" lower="-3.14" upper="3.14" /> 
     
  </joint>
  <link name="MP_ANKLE1_L">
    <inertial>
      <origin xyz="-0.000214 -0.018536 0.013873" />
      <mass value="0.16710792"/>
      <inertia ixx="0.12079175"  ixy="-0.00079781067"  ixz="-0.00039322246" iyx="-0.00079781067" iyy="0.10885465" iyz="0.0070770117" izx="-0.00039322246" izy="0.0070770117" izz="0.041871103" />
    </inertial>
    <visual>
      <origin rpy="0 0 0" xyz="0 0 0"/>
      <geometry>
        <mesh filename="package://exhx5_description/meshes/l_ank_pitch_link.STL"/>
      </geometry>
      <material name="">
        <color rgba="0.79216 0.81961 0.93333 1"/>
      </material>
    </visual>
    <collision>
      <origin rpy="0 0 0" xyz="0 0 0"/>
      <geometry>
        <mesh filename="package://exhx5_description/meshes/l_ank_pitch_link.STL"/>
      </geometry>
    </collision>
  </link>
  <joint name="j_ankle1_l" type="revolute">
    <origin rpy="0.0010451 -0.0023036 -0.42593" xyz="0.059298 0 0"/>
    <parent link="MP_TIBIA_L"/>
    <child link="MP_ANKLE1_L"/>
    <axis xyz="0 0 -1"/>
    <limit effort="1000" velocity="100" lower="-3.14" upper="3.14" /> 
     
  </joint>
  <link name="MP_ANKLE2_L">
    <inertial>
      <origin xyz="-0.025995 -0.009506 -0.000503" />
      <mass value="0.0794462"/>
      <inertia ixx="0.12079175"  ixy="-0.00079781067"  ixz="-0.00039322246" iyx="-0.00079781067" iyy="0.10885465" iyz="0.0070770117" izx="-0.00039322246" izy="0.0070770117" izz="0.041871103" />
    </inertial>
    <visual>
      <origin rpy="0 0 0" xyz="0 0 0"/>
      <geometry>
        <mesh filename="package://exhx5_description/meshes/l_ank_roll_link.STL"/>
      </geometry>
      <material name="">
        <color rgba="0.79216 0.81961 0.93333 1"/>
      </material>
    </visual>
    <collision>
      <origin rpy="0 0 0" xyz="0 0 0"/>
      <geometry>
        <mesh filename="package://exhx5_description/meshes/l_ank_roll_link.STL"/>
      </geometry>
    </collision>
  </link>
  <joint name="j_ankle2_l" type="revolute">
    <origin rpy="-1.5708 0 0" xyz="0.0465 0 0"/>
    <parent link="MP_ANKLE1_L"/>
    <child link="MP_ANKLE2_L"/>
    <axis xyz="0 0 1"/>
    <limit effort="1000" velocity="100" lower="-3.14" upper="3.14" /> 
     
  </joint>
  <link name="MP_NECK">
    <inertial>
      <origin rpy="0 0 0" xyz="0.023537 -0.003724 -0.00028487"/>

      <!--<mass value="0.1662"/>-->
      <mass value="0.1662"/>
      <inertia ixx="6.6503E-05" ixy="1.0732E-06" ixz="6.9267E-06" iyy="0.00022623" iyz="4.8946E-06" izz="0.00025375"/>
    </inertial>
    <visual>
      <origin rpy="0 0 0" xyz="0 0 0"/>
      <geometry>
        <mesh filename="package://exhx5_description/meshes/neck_pitch_link.STL"/>
      </geometry>
      <material name="">
        <color rgba="0.79216 0.81961 0.93333 1"/>
      </material>
    </visual>
    <collision>
      <origin rpy="0 0 0" xyz="0 0 0"/>
      <geometry>
        <mesh filename="package://exhx5_description/meshes/neck_pitch_link.STL"/>
      </geometry>
    </collision>
  </link>
  <joint name="j_pan" type="revolute">
    <origin rpy="1.5708 -1.5708 0" xyz="0.08865 0 0.10254"/>
    <parent link="MP_BODY"/>
    <child link="MP_NECK"/>
    <axis xyz="0 0 -1"/>
    <limit effort="1000" velocity="100" lower="-3.14" upper="3.14" /> 
     
  </joint>
  <link name="MP_HEAD">
    <inertial>
      <origin rpy="0 0 0" xyz="-0.00070546 0.013146 0.00027149"/>
      <mass value="0.0061954"/>
      <inertia ixx="5.3428E-07" ixy="-1.5374E-08" ixz="-3.8762E-09" iyy="5.8024E-07" iyz="1.3817E-08" izz="4.6408E-07"/>
    </inertial>
    <visual>
      <origin rpy="0 0 0" xyz="0 0 0"/>
      <geometry>
        <mesh filename="package://exhx5_description/meshes/head_tilt_link.STL"/>
      </geometry>
      <material name="">
        <color rgba="0.7451 0.7451 0.7451 1"/>
      </material>
    </visual>
    <collision>
      <origin rpy="0 0 0" xyz="0 0 0"/>
      <geometry>
        <mesh filename="package://exhx5_description/meshes/head_tilt_link.STL"/>
      </geometry>
    </collision>
  </link>
  <joint name="j_tilt" type="revolute">
    <origin rpy="0 0 -1.5708" xyz="0.14528 0 0"/>
    <parent link="MP_NECK"/>
    <child link="MP_HEAD"/>
    <axis xyz="0 0 -1"/>
    <limit effort="1000" velocity="100" lower="-3.14" upper="3.14" /> 
     
  </joint>
  <link name="MP_PMDCAMBOARD">
    <inertial>
      <origin rpy="0 0 0" xyz="0.0052568 -9.7868E-05 0.053166"/>
      <mass value="0.039218"/>
      <!--mass value="0.039218"/-->
      <inertia ixx="2.6979E-05" ixy="-3.471E-09" ixz="-1.7411E-06" iyy="1.8556E-05" iyz="-6.4409E-08" izz="2.0489E-05"/>
    </inertial>
    <visual>
      <origin rpy="0 0 0" xyz="0 0 0"/>
      <geometry>
        <mesh filename="package://exhx5_description/meshes/head_pan_link.STL"/>
      </geometry>
      <material name="">
        <color rgba="0.75294 0.75294 0.75294 1"/>
      </material>
    </visual>
    <collision>
      <origin rpy="0 0 0" xyz="0 0 0"/>
      <geometry>
        <mesh filename="package://exhx5_description/meshes/head_pan_link.STL"/>
      </geometry>
    </collision>
  </link>
  <joint name="j_camboard" type="revolute">
    <origin rpy="-1.5708 0 0" xyz="0 0 0"/>
    <parent link="MP_HEAD"/>
    <child link="MP_PMDCAMBOARD"/>
    <axis xyz="0 0 -1"/>
    <limit effort="1000" velocity="100" lower="-3.14" upper="3.14" /> 
     
  </joint>
  <transmission name="j_pelvis_r_tran">
    <type>transmission_interface/SimpleTransmission</type>
    <joint name="j_pelvis_r">
      <hardwareInterface>hardware_interface/EffortJointInterface</hardwareInterface>
    </joint>
    <actuator name="j_pelvis_r_motor">
      <hardwareInterface>hardware_interface/EffortJointInterface</hardwareInterface>
      <mechanicalReduction>1</mechanicalReduction>
    </actuator>
  </transmission>
  <transmission name="j_thigh1_r_tran">
    <type>transmission_interface/SimpleTransmission</type>
    <joint name="j_thigh1_r">
      <hardwareInterface>hardware_interface/EffortJointInterface</hardwareInterface>
    </joint>
    <actuator name="j_thigh1_r_motor">
      <hardwareInterface>hardware_interface/EffortJointInterface</hardwareInterface>
      <mechanicalReduction>1</mechanicalReduction>
    </actuator>
  </transmission>
  <transmission name="j_thigh2_r_tran">
    <type>transmission_interface/SimpleTransmission</type>
    <joint name="j_thigh2_r">
      <hardwareInterface>hardware_interface/EffortJointInterface</hardwareInterface>
    </joint>
    <actuator name="j_thigh2_r_motor">
      <hardwareInterface>hardware_interface/EffortJointInterface</hardwareInterface>
      <mechanicalReduction>1</mechanicalReduction>
    </actuator>
  </transmission>
  <transmission name="j_tibia_r_tran">
    <type>transmission_interface/SimpleTransmission</type>
    <joint name="j_tibia_r">
      <hardwareInterface>hardware_interface/EffortJointInterface</hardwareInterface>
    </joint>
    <actuator name="j_tibia_r_motor">
      <hardwareInterface>hardware_interface/EffortJointInterface</hardwareInterface>
      <mechanicalReduction>1</mechanicalReduction>
    </actuator>
  </transmission>
  <transmission name="j_ankle1_r_tran">
    <type>transmission_interface/SimpleTransmission</type>
    <joint name="j_ankle1_r">
      <hardwareInterface>hardware_interface/EffortJointInterface</hardwareInterface>
    </joint>
    <actuator name="j_ankle1_r_motor">
      <hardwareInterface>hardware_interface/EffortJointInterface</hardwareInterface>
      <mechanicalReduction>1</mechanicalReduction>
    </actuator>
  </transmission>
  <transmission name="j_ankle2_r_tran">
    <type>transmission_interface/SimpleTransmission</type>
    <joint name="j_ankle2_r">
      <hardwareInterface>hardware_interface/EffortJointInterface</hardwareInterface>
    </joint>
    <actuator name="j_ankle2_r_motor">
      <hardwareInterface>hardware_interface/EffortJointInterface</hardwareInterface>
      <mechanicalReduction>1</mechanicalReduction>
    </actuator>
  </transmission>
  <transmission name="j_pelvis_l_tran">
    <type>transmission_interface/SimpleTransmission</type>
    <joint name="j_pelvis_l">
      <hardwareInterface>hardware_interface/EffortJointInterface</hardwareInterface>
    </joint>
    <actuator name="j_pelvis_l_motor">
      <hardwareInterface>hardware_interface/EffortJointInterface</hardwareInterface>
      <mechanicalReduction>1</mechanicalReduction>
    </actuator>
  </transmission>
  <transmission name="j_thigh1_l_tran">
    <type>transmission_interface/SimpleTransmission</type>
    <joint name="j_thigh1_l">
      <hardwareInterface>hardware_interface/EffortJointInterface</hardwareInterface>
    </joint>
    <actuator name="j_thigh1_l_motor">
      <hardwareInterface>hardware_interface/EffortJointInterface</hardwareInterface>
      <mechanicalReduction>1</mechanicalReduction>
    </actuator>
  </transmission>
  <transmission name="j_thigh2_l_tran">
    <type>transmission_interface/SimpleTransmission</type>
    <joint name="j_thigh2_l">
      <hardwareInterface>hardware_interface/EffortJointInterface</hardwareInterface>
    </joint>
    <actuator name="j_thigh2_l_motor">
      <hardwareInterface>hardware_interface/EffortJointInterface</hardwareInterface>
      <mechanicalReduction>1</mechanicalReduction>
    </actuator>
  </transmission>
  <transmission name="j_tibia_l_tran">
    <type>transmission_interface/SimpleTransmission</type>
    <joint name="j_tibia_l">
      <hardwareInterface>hardware_interface/EffortJointInterface</hardwareInterface>
    </joint>
    <actuator name="j_tibia_l_motor">
      <hardwareInterface>hardware_interface/EffortJointInterface</hardwareInterface>
      <mechanicalReduction>1</mechanicalReduction>
    </actuator>
  </transmission>
  <transmission name="j_ankle1_l_tran">
    <type>transmission_interface/SimpleTransmission</type>
    <joint name="j_ankle1_l">
      <hardwareInterface>hardware_interface/EffortJointInterface</hardwareInterface>
    </joint>
    <actuator name="j_ankle1_l_motor">
      <hardwareInterface>hardware_interface/EffortJointInterface</hardwareInterface>
      <mechanicalReduction>1</mechanicalReduction>
    </actuator>
  </transmission>
  <transmission name="j_ankle2_l_tran">
    <type>transmission_interface/SimpleTransmission</type>
    <joint name="j_ankle2_l">
      <hardwareInterface>hardware_interface/EffortJointInterface</hardwareInterface>
    </joint>
    <actuator name="j_ankle2_l_motor">
      <hardwareInterface>hardware_interface/EffortJointInterface</hardwareInterface>
      <mechanicalReduction>1</mechanicalReduction>
    </actuator>
  </transmission>
  <transmission name="j_pan_tran">
    <type>transmission_interface/SimpleTransmission</type>
    <joint name="j_pan">
      <hardwareInterface>hardware_interface/EffortJointInterface</hardwareInterface>
    </joint>
    <actuator name="j_pan_motor">
      <hardwareInterface>hardware_interface/EffortJointInterface</hardwareInterface>
      <mechanicalReduction>1</mechanicalReduction>
    </actuator>
  </transmission>
  <transmission name="j_tilt_tran">
    <type>transmission_interface/SimpleTransmission</type>
    <joint name="j_tilt">
      <hardwareInterface>hardware_interface/EffortJointInterface</hardwareInterface>
    </joint>
    <actuator name="j_tilt_motor">
      <hardwareInterface>hardware_interface/EffortJointInterface</hardwareInterface>
      <mechanicalReduction>1</mechanicalReduction>
    </actuator>
  </transmission>
  <transmission name="j_camboard_tran">
    <type>transmission_interface/SimpleTransmission</type>
    <joint name="j_camboard">
      <hardwareInterface>hardware_interface/EffortJointInterface</hardwareInterface>
    </joint>
    <actuator name="j_camboard_motor">
      <hardwareInterface>hardware_interface/EffortJointInterface</hardwareInterface>
      <mechanicalReduction>1</mechanicalReduction>
    </actuator>
  </transmission>
</robot>

