<?xml version="1.0" encoding="utf-8"?>
<!-- This URDF was automatically created by SolidWorks to URDF Exporter! Originally created by Stephen Brawner (brawner@gmail.com) 
     Commit Version: 1.5.0-0-g9aa0fdb  Build Version: 1.5.7004.21443
     For more information, please see http://wiki.ros.org/sw_urdf_exporter -->
<robot
  name="exhx5">
  <link
    name="body_link">
    <inertial>
      <origin
        xyz="-0.024506 -3.2231E-05 0.033725"
        rpy="0 0 0" />
      <mass
        value="0.75842" />
      <inertia
        ixx="0.0018267"
        ixy="-0.00016368"
        ixz="-0.00022149"
        iyy="0.0028108"
        iyz="-5.9556E-06"
        izz="0.0041242" />
    </inertial>
    <visual>
      <origin
        xyz="0 0 0"
        rpy="0 0 0" />
      <geometry>
        <mesh
          filename="package://exhx5_description/meshes/body_link.STL" />
      </geometry>
      <material
        name="">
        <color
          rgba="0.79216 0.81961 0.93333 1" />
      </material>
    </visual>
    <collision>
      <origin
        xyz="0 0 0"
        rpy="0 0 0" />
      <geometry>
        <mesh
          filename="package://exhx5_description/meshes/body_link.STL" />
      </geometry>
    </collision>
  </link>
  <link
    name="r_hip_yaw_link">
    <inertial>
      <origin
        xyz="6.9389E-16 0.00049037 0.015811"
        rpy="0 0 0" />
      <mass
        value="0.017594" />
      <inertia
        ixx="8.0769E-06"
        ixy="9.3231E-20"
        ixz="-6.8781E-20"
        iyy="3.8081E-06"
        iyz="4.4924E-07"
        izz="6.9409E-06" />
    </inertial>
    <visual>
      <origin
        xyz="0 0 0"
        rpy="0 0 0" />
      <geometry>
        <mesh
          filename="package://exhx5_description/meshes/r_hip_yaw_link.STL" />
      </geometry>
      <material
        name="">
        <color
          rgba="0.79216 0.81961 0.93333 1" />
      </material>
    </visual>
    <collision>
      <origin
        xyz="0 0 0"
        rpy="0 0 0" />
      <geometry>
        <mesh
          filename="package://exhx5_description/meshes/r_hip_yaw_link.STL" />
      </geometry>
    </collision>
  </link>
  <joint
    name="r_hip_yaw"
    type="revolute">
    <origin
      xyz="0 -0.0539999999999998 -0.024500000000006"
      rpy="0 0 1.57079632679488" />
    <parent
      link="body_link" />
    <child
      link="r_hip_yaw_link" />
    <axis
      xyz="0 0 1" />
    <limit
      lower="-1.57"
      upper="1.57"
      effort="0"
      velocity="0" />
    <safety_controller
      k_velocity="0" />
  </joint>
  <link
    name="r_hip_roll_link">
    <inertial>
      <origin
        xyz="0.013265 -0.00034234 -0.01908"
        rpy="0 0 0" />
      <mass
        value="0.10053" />
      <inertia
        ixx="1.7395E-05"
        ixy="-2.6908E-07"
        ixz="3.1908E-07"
        iyy="2.5171E-05"
        iyz="-1.1436E-12"
        izz="2.5299E-05" />
    </inertial>
    <visual>
      <origin
        xyz="0 0 0"
        rpy="0 0 0" />
      <geometry>
        <mesh
          filename="package://exhx5_description/meshes/r_hip_roll_link.STL" />
      </geometry>
      <material
        name="">
        <color
          rgba="0.79216 0.81961 0.93333 1" />
      </material>
    </visual>
    <collision>
      <origin
        xyz="0 0 0"
        rpy="0 0 0" />
      <geometry>
        <mesh
          filename="package://exhx5_description/meshes/r_hip_roll_link.STL" />
      </geometry>
    </collision>
  </link>
  <joint
    name="r_hip_roll"
    type="revolute">
    <origin
      xyz="0 0 0"
      rpy="1.5708 1.5708 0" />
    <parent
      link="r_hip_yaw_link" />
    <child
      link="r_hip_roll_link" />
    <axis
      xyz="0 0 1" />
    <limit
      lower="-1.57"
      upper="1.57"
      effort="0"
      velocity="0" />
    <safety_controller
      k_velocity="0" />
  </joint>
  <link
    name="r_hip_pitch_link">
    <inertial>
      <origin
        xyz="0.041705 0.0061699 2.177E-08"
        rpy="0 0 0" />
      <mass
        value="0.023646" />
      <inertia
        ixx="1.2406E-05"
        ixy="-7.7791E-07"
        ixz="9.7606E-13"
        iyy="2.2891E-05"
        iyz="4.5062E-12"
        izz="1.4533E-05" />
    </inertial>
    <visual>
      <origin
        xyz="0 0 0"
        rpy="0 0 0" />
      <geometry>
        <mesh
          filename="package://exhx5_description/meshes/r_hip_pitch_link.STL" />
      </geometry>
      <material
        name="">
        <color
          rgba="0.79216 0.81961 0.93333 1" />
      </material>
    </visual>
    <collision>
      <origin
        xyz="0 0 0"
        rpy="0 0 0" />
      <geometry>
        <mesh
          filename="package://exhx5_description/meshes/r_hip_pitch_link.STL" />
      </geometry>
    </collision>
  </link>
  <joint
    name="r_hip_pitch"
    type="revolute">
    <origin
      xyz="0 0 0"
      rpy="1.5708 0 0" />
    <parent
      link="r_hip_roll_link" />
    <child
      link="r_hip_pitch_link" />
    <axis
      xyz="0 0 1" />
    <limit
      lower="-1.57"
      upper="1.57"
      effort="0"
      velocity="0" />
    <safety_controller
      k_velocity="0" />
  </joint>
  <link
    name="r_knee_link">
    <inertial>
      <origin
        xyz="0.025579 0.0091776 0.00042921"
        rpy="0 0 0" />
      <mass
        value="0.10139" />
      <inertia
        ixx="2.4558E-05"
        ixy="4.9361E-07"
        ixz="-1.2228E-07"
        iyy="2.2855E-05"
        iyz="3.2346E-07"
        izz="2.5943E-05" />
    </inertial>
    <visual>
      <origin
        xyz="0 0 0"
        rpy="0 0 0" />
      <geometry>
        <mesh
          filename="package://exhx5_description/meshes/r_knee_link.STL" />
      </geometry>
      <material
        name="">
        <color
          rgba="0.79216 0.81961 0.93333 1" />
      </material>
    </visual>
    <collision>
      <origin
        xyz="0 0 0"
        rpy="0 0 0" />
      <geometry>
        <mesh
          filename="package://exhx5_description/meshes/r_knee_link.STL" />
      </geometry>
    </collision>
  </link>
  <joint
    name="r_knee"
    type="revolute">
    <origin
      xyz="0.075954 0 0"
      rpy="0 0.0004216 0.42593" />
    <parent
      link="r_hip_pitch_link" />
    <child
      link="r_knee_link" />
    <axis
      xyz="-0.0004216 0 1" />
    <limit
      lower="-1.57"
      upper="1.57"
      effort="0"
      velocity="0" />
    <safety_controller
      k_velocity="0" />
  </joint>
  <link
    name="r_ank_pitch_link">
    <inertial>
      <origin
        xyz="0.02325 -2.2204E-16 1.3878E-17"
        rpy="0 0 0" />
      <mass
        value="0.0095421" />
      <inertia
        ixx="3.5492E-06"
        ixy="1.0553E-21"
        ixz="1.8686E-21"
        iyy="2.8994E-06"
        iyz="-8.2951E-22"
        izz="2.8994E-06" />
    </inertial>
    <visual>
      <origin
        xyz="0 0 0"
        rpy="0 0 0" />
      <geometry>
        <mesh
          filename="package://exhx5_description/meshes/r_ank_pitch_link.STL" />
      </geometry>
      <material
        name="">
        <color
          rgba="0.79216 0.81961 0.93333 1" />
      </material>
    </visual>
    <collision>
      <origin
        xyz="0 0 0"
        rpy="0 0 0" />
      <geometry>
        <mesh
          filename="package://exhx5_description/meshes/r_ank_pitch_link.STL" />
      </geometry>
    </collision>
  </link>
  <joint
    name="r_ank_pitch"
    type="revolute">
    <origin
      xyz="0.059298 0 0"
      rpy="0.00017419 -0.00038393 -0.42593" />
    <parent
      link="r_knee_link" />
    <child
      link="r_ank_pitch_link" />
    <axis
      xyz="0 0 1" />
    <limit
      lower="-1.57"
      upper="1.57"
      effort="0"
      velocity="0" />
    <safety_controller
      k_velocity="0" />
  </joint>
  <link
    name="r_ank_roll">
    <inertial>
      <origin
        xyz="0.00474 -0.010189 0.017732"
        rpy="0 0 0" />
      <mass
        value="0.1244" />
      <inertia
        ixx="0.00013147"
        ixy="1.1537E-08"
        ixz="1.5896E-06"
        iyy="9.5366E-05"
        iyz="-2.4562E-07"
        izz="4.9024E-05" />
    </inertial>
    <visual>
      <origin
        xyz="0 0 0"
        rpy="0 0 0" />
      <geometry>
        <mesh
          filename="package://exhx5_description/meshes/r_ank_roll.STL" />
      </geometry>
      <material
        name="">
        <color
          rgba="0.79216 0.81961 0.93333 1" />
      </material>
    </visual>
    <collision>
      <origin
        xyz="0 0 0"
        rpy="0 0 0" />
      <geometry>
        <mesh
          filename="package://exhx5_description/meshes/r_ank_roll.STL" />
      </geometry>
    </collision>
  </link>
  <joint
    name="r_ank_roll_link"
    type="revolute">
    <origin
      xyz="0.0465 0 0"
      rpy="-1.5708 0 0" />
    <parent
      link="r_ank_pitch_link" />
    <child
      link="r_ank_roll" />
    <axis
      xyz="0 0 1" />
    <limit
      lower="-1.57"
      upper="1.57"
      effort="0"
      velocity="0" />
    <safety_controller
      k_velocity="0" />
  </joint>
  <link
    name="l_hip_yaw_link">
    <inertial>
      <origin
        xyz="2.5674E-16 0.00049037 0.015811"
        rpy="0 0 0" />
      <mass
        value="0.017594" />
      <inertia
        ixx="8.0769E-06"
        ixy="9.4844E-20"
        ixz="-7.0787E-20"
        iyy="3.8081E-06"
        iyz="4.4924E-07"
        izz="6.9409E-06" />
    </inertial>
    <visual>
      <origin
        xyz="0 0 0"
        rpy="0 0 0" />
      <geometry>
        <mesh
          filename="package://exhx5_description/meshes/l_hip_yaw_link.STL" />
      </geometry>
      <material
        name="">
        <color
          rgba="0.79216 0.81961 0.93333 1" />
      </material>
    </visual>
    <collision>
      <origin
        xyz="0 0 0"
        rpy="0 0 0" />
      <geometry>
        <mesh
          filename="package://exhx5_description/meshes/l_hip_yaw_link.STL" />
      </geometry>
    </collision>
  </link>
  <joint
    name="l_hip_yaw"
    type="revolute">
    <origin
      xyz="0 0.054 -0.0245"
      rpy="0 0 1.5708" />
    <parent
      link="body_link" />
    <child
      link="l_hip_yaw_link" />
    <axis
      xyz="-2.8454E-05 0 1" />
    <limit
      lower="-1.57"
      upper="1.57"
      effort="0"
      velocity="0" />
    <safety_controller
      k_velocity="0" />
  </joint>
  <link
    name="l_hip_roll_link">
    <inertial>
      <origin
        xyz="0.013576 -0.00035038 -0.020028"
        rpy="0 0 0" />
      <mass
        value="0.098221" />
      <inertia
        ixx="1.7307E-05"
        ixy="-2.6908E-07"
        ixz="3.1908E-07"
        iyy="2.5083E-05"
        iyz="-1.1436E-12"
        izz="2.5141E-05" />
    </inertial>
    <visual>
      <origin
        xyz="0 0 0"
        rpy="0 0 0" />
      <geometry>
        <mesh
          filename="package://exhx5_description/meshes/l_hip_roll_link.STL" />
      </geometry>
      <material
        name="">
        <color
          rgba="0.79216 0.81961 0.93333 1" />
      </material>
    </visual>
    <collision>
      <origin
        xyz="0 0 0"
        rpy="0 0 0" />
      <geometry>
        <mesh
          filename="package://exhx5_description/meshes/l_hip_roll_link.STL" />
      </geometry>
    </collision>
  </link>
  <joint
    name="l_hip_roll"
    type="revolute">
    <origin
      xyz="0 0 0"
      rpy="1.5708 1.5708 0" />
    <parent
      link="l_hip_yaw_link" />
    <child
      link="l_hip_roll_link" />
    <axis
      xyz="0 0 1" />
    <limit
      lower="-1.57"
      upper="1.57"
      effort="0"
      velocity="0" />
    <safety_controller
      k_velocity="0" />
  </joint>
  <link
    name="l_hip_pitch_link">
    <inertial>
      <origin
        xyz="0.041705 0.0061699 2.1346E-08"
        rpy="0 0 0" />
      <mass
        value="0.023646" />
      <inertia
        ixx="1.2406E-05"
        ixy="-7.7791E-07"
        ixz="8.1343E-13"
        iyy="2.2891E-05"
        iyz="4.6012E-12"
        izz="1.4533E-05" />
    </inertial>
    <visual>
      <origin
        xyz="0 0 0"
        rpy="0 0 0" />
      <geometry>
        <mesh
          filename="package://exhx5_description/meshes/l_hip_pitch_link.STL" />
      </geometry>
      <material
        name="">
        <color
          rgba="0.79216 0.81961 0.93333 1" />
      </material>
    </visual>
    <collision>
      <origin
        xyz="0 0 0"
        rpy="0 0 0" />
      <geometry>
        <mesh
          filename="package://exhx5_description/meshes/l_hip_pitch_link.STL" />
      </geometry>
    </collision>
  </link>
  <joint
    name="l_hip_pitch"
    type="revolute">
    <origin
      xyz="0 0 0"
      rpy="1.5708 0 0" />
    <parent
      link="l_hip_roll_link" />
    <child
      link="l_hip_pitch_link" />
    <axis
      xyz="0 0 -1" />
    <limit
      lower="-1.57"
      upper="1.57"
      effort="0"
      velocity="0" />
    <safety_controller
      k_velocity="0" />
  </joint>
  <link
    name="l_knee_link">
    <inertial>
      <origin
        xyz="0.025567 0.0092446 0.00043028"
        rpy="0 0 0" />
      <mass
        value="0.10219" />
      <inertia
        ixx="2.4767E-05"
        ixy="5.0737E-07"
        ixz="-1.2513E-07"
        iyy="2.3061E-05"
        iyz="3.2454E-07"
        izz="2.6112E-05" />
    </inertial>
    <visual>
      <origin
        xyz="0 0 0"
        rpy="0 0 0" />
      <geometry>
        <mesh
          filename="package://exhx5_description/meshes/l_knee_link.STL" />
      </geometry>
      <material
        name="">
        <color
          rgba="0.79216 0.81961 0.93333 1" />
      </material>
    </visual>
    <collision>
      <origin
        xyz="0 0 0"
        rpy="0 0 0" />
      <geometry>
        <mesh
          filename="package://exhx5_description/meshes/l_knee_link.STL" />
      </geometry>
    </collision>
  </link>
  <joint
    name="l_knee"
    type="revolute">
    <origin
      xyz="0.075954 0 0"
      rpy="0 0.0025296 0.42593" />
    <parent
      link="l_hip_pitch_link" />
    <child
      link="l_knee_link" />
    <axis
      xyz="0.0025296 0 -1" />
    <limit
      lower="-1.57"
      upper="1.57"
      effort="0"
      velocity="0" />
    <safety_controller
      k_velocity="0" />
  </joint>
  <link
    name="l_ank_pitch_link">
    <inertial>
      <origin
        xyz="0.02325 2.3176E-15 -1.4919E-15"
        rpy="0 0 0" />
      <mass
        value="0.0095421" />
      <inertia
        ixx="3.5492E-06"
        ixy="-5.3001E-21"
        ixz="1.6479E-21"
        iyy="2.8994E-06"
        iyz="-6.6441E-22"
        izz="2.8994E-06" />
    </inertial>
    <visual>
      <origin
        xyz="0 0 0"
        rpy="0 0 0" />
      <geometry>
        <mesh
          filename="package://exhx5_description/meshes/l_ank_pitch_link.STL" />
      </geometry>
      <material
        name="">
        <color
          rgba="0.79216 0.81961 0.93333 1" />
      </material>
    </visual>
    <collision>
      <origin
        xyz="0 0 0"
        rpy="0 0 0" />
      <geometry>
        <mesh
          filename="package://exhx5_description/meshes/l_ank_pitch_link.STL" />
      </geometry>
    </collision>
  </link>
  <joint
    name="l_ank_pitch"
    type="revolute">
    <origin
      xyz="0.059298 0 0"
      rpy="0.0010451 -0.0023036 -0.42593" />
    <parent
      link="l_knee_link" />
    <child
      link="l_ank_pitch_link" />
    <axis
      xyz="0 0 1" />
    <limit
      lower="-1.57"
      upper="1.57"
      effort="0"
      velocity="0" />
    <safety_controller
      k_velocity="0" />
  </joint>
  <link
    name="l_ank_roll_link">
    <inertial>
      <origin
        xyz="0.004986 0.0099744 0.020867"
        rpy="0 0 0" />
      <mass
        value="0.13679" />
      <inertia
        ixx="0.00013651"
        ixy="1.0973E-06"
        ixz="-1.4778E-07"
        iyy="9.9705E-05"
        iyz="2.0814E-06"
        izz="5.2371E-05" />
    </inertial>
    <visual>
      <origin
        xyz="0 0 0"
        rpy="0 0 0" />
      <geometry>
        <mesh
          filename="package://exhx5_description/meshes/l_ank_roll_link.STL" />
      </geometry>
      <material
        name="">
        <color
          rgba="0.79216 0.81961 0.93333 1" />
      </material>
    </visual>
    <collision>
      <origin
        xyz="0 0 0"
        rpy="0 0 0" />
      <geometry>
        <mesh
          filename="package://exhx5_description/meshes/l_ank_roll_link.STL" />
      </geometry>
    </collision>
  </link>
  <joint
    name="l_ank_roll"
    type="revolute">
    <origin
      xyz="0.0465 0 0"
      rpy="-1.5708 0 0" />
    <parent
      link="l_ank_pitch_link" />
    <child
      link="l_ank_roll_link" />
    <axis
      xyz="0 0 1" />
    <limit
      lower="-1.57"
      upper="1.57"
      effort="0"
      velocity="0" />
    <safety_controller
      k_velocity="0" />
  </joint>
  <link
    name="neck_pitch_link">
    <inertial>
      <origin
        xyz="0.023537 -0.003724 -0.00028487"
        rpy="0 0 0" />
      <mass
        value="0.1662" />
      <inertia
        ixx="6.6503E-05"
        ixy="1.0732E-06"
        ixz="6.9267E-06"
        iyy="0.00022623"
        iyz="4.8946E-06"
        izz="0.00025375" />
    </inertial>
    <visual>
      <origin
        xyz="0 0 0"
        rpy="0 0 0" />
      <geometry>
        <mesh
          filename="package://exhx5_description/meshes/neck_pitch_link.STL" />
      </geometry>
      <material
        name="">
        <color
          rgba="0.79216 0.81961 0.93333 1" />
      </material>
    </visual>
    <collision>
      <origin
        xyz="0 0 0"
        rpy="0 0 0" />
      <geometry>
        <mesh
          filename="package://exhx5_description/meshes/neck_pitch_link.STL" />
      </geometry>
    </collision>
  </link>
  <joint
    name="neck_pitch"
    type="revolute">
    <origin
      xyz="0.08865 0 0.10254"
      rpy="1.5708 -1.5708 0" />
    <parent
      link="body_link" />
    <child
      link="neck_pitch_link" />
    <axis
      xyz="0 0 -1" />
    <limit
      lower="-1.57"
      upper="1.57"
      effort="0"
      velocity="0" />
    <safety_controller
      k_velocity="0" />
  </joint>
  <link
    name="head_tilt_link">
    <inertial>
      <origin
        xyz="-0.00070546 0.013146 0.00027149"
        rpy="0 0 0" />
      <mass
        value="0.0061954" />
      <inertia
        ixx="5.3428E-07"
        ixy="-1.5374E-08"
        ixz="-3.8762E-09"
        iyy="5.8024E-07"
        iyz="1.3817E-08"
        izz="4.6408E-07" />
    </inertial>
    <visual>
      <origin
        xyz="0 0 0"
        rpy="0 0 0" />
      <geometry>
        <mesh
          filename="package://exhx5_description/meshes/head_tilt_link.STL" />
      </geometry>
      <material
        name="">
        <color
          rgba="0.7451 0.7451 0.7451 1" />
      </material>
    </visual>
    <collision>
      <origin
        xyz="0 0 0"
        rpy="0 0 0" />
      <geometry>
        <mesh
          filename="package://exhx5_description/meshes/head_tilt_link.STL" />
      </geometry>
    </collision>
  </link>
  <joint
    name="head_tilt"
    type="revolute">
    <origin
      xyz="0.14528 0 0"
      rpy="0 0 -1.5708" />
    <parent
      link="neck_pitch_link" />
    <child
      link="head_tilt_link" />
    <axis
      xyz="0 0 -1" />
    <limit
      lower="-1.57"
      upper="1.57"
      effort="0"
      velocity="0" />
    <safety_controller
      k_velocity="0" />
  </joint>
  <link
    name="head_pan_link">
    <inertial>
      <origin
        xyz="0.0052568 -9.7868E-05 0.053166"
        rpy="0 0 0" />
      <mass
        value="0.039218" />
      <inertia
        ixx="2.6979E-05"
        ixy="-3.471E-09"
        ixz="-1.7411E-06"
        iyy="1.8556E-05"
        iyz="-6.4409E-08"
        izz="2.0489E-05" />
    </inertial>
    <visual>
      <origin
        xyz="0 0 0"
        rpy="0 0 0" />
      <geometry>
        <mesh
          filename="package://exhx5_description/meshes/head_pan_link.STL" />
      </geometry>
      <material
        name="">
        <color
          rgba="0.75294 0.75294 0.75294 1" />
      </material>
    </visual>
    <collision>
      <origin
        xyz="0 0 0"
        rpy="0 0 0" />
      <geometry>
        <mesh
          filename="package://exhx5_description/meshes/head_pan_link.STL" />
      </geometry>
    </collision>
  </link>
  <joint
    name="head_pan"
    type="revolute">
    <origin
      xyz="0 0 0"
      rpy="-1.5708 0 0" />
    <parent
      link="head_tilt_link" />
    <child
      link="head_pan_link" />
    <axis
      xyz="0 0 -1" />
    <limit
      lower="-1.57"
      upper="1.57"
      effort="0"
      velocity="0" />
    <safety_controller
      k_velocity="0" />
  </joint>
</robot>
