<?xml version="1.0" encoding="utf-8"?>
<!-- This URDF was automatically created by SolidWorks to URDF Exporter! Originally created by Stephen Brawner (brawner@gmail.com) 
     Commit Version: 1.5.0-0-g9aa0fdb  Build Version: 1.5.7004.21443
     For more information, please see http://wiki.ros.org/sw_urdf_exporter -->
<robot
  name="exhx5">
  <link
    name="base_link">
    <inertial>
      <origin
        xyz="-0.0195064127831315 -3.2230740095152E-05 -0.06882"
        rpy="0 0 0" />
      <mass
        value="0.758415754599216" />
      <inertia
        ixx="0.00182665419190017"
        ixy="-0.000163676492657619"
        ixz="-0.000221492415837962"
        iyy="0.00281082835406159"
        iyz="-5.95559183958398E-06"
        izz="0.00412416282266996" />
    </inertial>
    <visual>
      <origin
        xyz="0 0 0"
        rpy="0 0 0" />
      <geometry>
        <mesh
          filename="package://exhx5_description/meshes/base_link.STL" />
      </geometry>
      <material
        name="">
        <color
          rgba="0.792156862745098 0.819607843137255 0.933333333333333 1" />
      </material>
    </visual>
    <collision>
      <origin
        xyz="0 0 0"
        rpy="0 0 0" />
      <geometry>
        <mesh
          filename="package://exhx5_description/meshes/base_link.STL" />
      </geometry>
    </collision>
  </link>
  <link
    name="right_link_1">
    <inertial>
      <origin
        xyz="-1.8041E-16 0.00049037 0.015811"
        rpy="0 0 0" />
      <mass
        value="0.017594" />
      <inertia
        ixx="8.0769E-06"
        ixy="-1.1515E-22"
        ixz="1.2055E-21"
        iyy="3.8081E-06"
        iyz="4.4924E-07"
        izz="6.9409E-06" />
    </inertial>
    <visual>
      <origin
        xyz="0 0 0"
        rpy="0 0 0" />
      <geometry>
        <mesh
          filename="package://exhx5_description/meshes/right_link_1.STL" />
      </geometry>
      <material
        name="">
        <color
          rgba="0.79216 0.81961 0.93333 1" />
      </material>
    </visual>
    <collision>
      <origin
        xyz="0 0 0"
        rpy="0 0 0" />
      <geometry>
        <mesh
          filename="package://exhx5_description/meshes/right_link_1.STL" />
      </geometry>
    </collision>
  </link>
  <joint
    name="right_joint_1"
    type="revolute">
    <origin
      xyz="0.005 -0.054 0.1967"
      rpy="0 0 1.5708" />
    <parent
      link="base_link" />
    <child
      link="right_link_1" />
    <axis
      xyz="0 0 1" />
    <limit
      lower="-1.57"
      upper="1.57"
      effort="0"
      velocity="0" />
    <safety_controller
      k_velocity="0" />
  </joint>
  <link
    name="right_link_2">
    <inertial>
      <origin
        xyz="0.013265 -0.00034234 -0.01908"
        rpy="0 0 0" />
      <mass
        value="0.10053" />
      <inertia
        ixx="1.7395E-05"
        ixy="-2.6908E-07"
        ixz="3.1908E-07"
        iyy="2.5171E-05"
        iyz="-1.1436E-12"
        izz="2.5299E-05" />
    </inertial>
    <visual>
      <origin
        xyz="0 0 0"
        rpy="0 0 0" />
      <geometry>
        <mesh
          filename="package://exhx5_description/meshes/right_link_2.STL" />
      </geometry>
      <material
        name="">
        <color
          rgba="0.79216 0.81961 0.93333 1" />
      </material>
    </visual>
    <collision>
      <origin
        xyz="0 0 0"
        rpy="0 0 0" />
      <geometry>
        <mesh
          filename="package://exhx5_description/meshes/right_link_2.STL" />
      </geometry>
    </collision>
  </link>
  <joint
    name="right_joint_2"
    type="revolute">
    <origin
      xyz="0 0 0"
      rpy="1.5708 1.5708 0" />
    <parent
      link="right_link_1" />
    <child
      link="right_link_2" />
    <axis
      xyz="0 0 1" />
    <limit
      lower="-1.57"
      upper="1.57"
      effort="0"
      velocity="0" />
    <safety_controller
      k_velocity="0" />
  </joint>
  <link
    name="right_link_3">
    <inertial>
      <origin
        xyz="0.041705 0.0061699 2.177E-08"
        rpy="0 0 0" />
      <mass
        value="0.023646" />
      <inertia
        ixx="1.2406E-05"
        ixy="-7.7791E-07"
        ixz="9.7606E-13"
        iyy="2.2891E-05"
        iyz="4.5062E-12"
        izz="1.4533E-05" />
    </inertial>
    <visual>
      <origin
        xyz="0 0 0"
        rpy="0 0 0" />
      <geometry>
        <mesh
          filename="package://exhx5_description/meshes/right_link_3.STL" />
      </geometry>
      <material
        name="">
        <color
          rgba="0.79216 0.81961 0.93333 1" />
      </material>
    </visual>
    <collision>
      <origin
        xyz="0 0 0"
        rpy="0 0 0" />
      <geometry>
        <mesh
          filename="package://exhx5_description/meshes/right_link_3.STL" />
      </geometry>
    </collision>
  </link>
  <joint
    name="right_joint_3"
    type="revolute">
    <origin
      xyz="0 0 0"
      rpy="1.5708 0 0" />
    <parent
      link="right_link_2" />
    <child
      link="right_link_3" />
    <axis
      xyz="0 0 1" />
    <limit
      lower="-1.57"
      upper="1.57"
      effort="0"
      velocity="0" />
    <safety_controller
      k_velocity="0" />
  </joint>
  <link
    name="right_link_4">
    <inertial>
      <origin
        xyz="0.025579 0.0091776 0.00042921"
        rpy="0 0 0" />
      <mass
        value="0.10139" />
      <inertia
        ixx="2.4558E-05"
        ixy="4.9361E-07"
        ixz="-1.2228E-07"
        iyy="2.2855E-05"
        iyz="3.2346E-07"
        izz="2.5943E-05" />
    </inertial>
    <visual>
      <origin
        xyz="0 0 0"
        rpy="0 0 0" />
      <geometry>
        <mesh
          filename="package://exhx5_description/meshes/right_link_4.STL" />
      </geometry>
      <material
        name="">
        <color
          rgba="0.79216 0.81961 0.93333 1" />
      </material>
    </visual>
    <collision>
      <origin
        xyz="0 0 0"
        rpy="0 0 0" />
      <geometry>
        <mesh
          filename="package://exhx5_description/meshes/right_link_4.STL" />
      </geometry>
    </collision>
  </link>
  <joint
    name="right_joint_4"
    type="revolute">
    <origin
      xyz="0.075954 0 0"
      rpy="0 0.0004216 0.42593" />
    <parent
      link="right_link_3" />
    <child
      link="right_link_4" />
    <axis
      xyz="-0.0004216 0 1" />
    <limit
      lower="-1.57"
      upper="1.57"
      effort="0"
      velocity="0" />
    <safety_controller
      k_velocity="0" />
  </joint>
  <link
    name="right_link_5">
    <inertial>
      <origin
        xyz="0.02325 -2.2204E-16 1.3878E-17"
        rpy="0 0 0" />
      <mass
        value="0.0095421" />
      <inertia
        ixx="3.5492E-06"
        ixy="8.9939E-22"
        ixz="1.7708E-21"
        iyy="2.8994E-06"
        iyz="-8.4011E-22"
        izz="2.8994E-06" />
    </inertial>
    <visual>
      <origin
        xyz="0 0 0"
        rpy="0 0 0" />
      <geometry>
        <mesh
          filename="package://exhx5_description/meshes/right_link_5.STL" />
      </geometry>
      <material
        name="">
        <color
          rgba="0.79216 0.81961 0.93333 1" />
      </material>
    </visual>
    <collision>
      <origin
        xyz="0 0 0"
        rpy="0 0 0" />
      <geometry>
        <mesh
          filename="package://exhx5_description/meshes/right_link_5.STL" />
      </geometry>
    </collision>
  </link>
  <joint
    name="right_joint_5"
    type="revolute">
    <origin
      xyz="0.059298 0 0"
      rpy="0.00017419 -0.00038393 -0.42593" />
    <parent
      link="right_link_4" />
    <child
      link="right_link_5" />
    <axis
      xyz="0 0 1" />
    <limit
      lower="-1.57"
      upper="1.57"
      effort="0"
      velocity="0" />
    <safety_controller
      k_velocity="0" />
  </joint>
  <link
    name="right_link_6">
    <inertial>
      <origin
        xyz="0.007201 -0.010523 0.016171"
        rpy="0 0 0" />
      <mass
        value="0.10557" />
      <inertia
        ixx="0.00010084"
        ixy="1.1494E-08"
        ixz="2.197E-06"
        iyy="8.062E-05"
        iyz="-2.9695E-07"
        izz="2.9905E-05" />
    </inertial>
    <visual>
      <origin
        xyz="0 0 0"
        rpy="0 0 0" />
      <geometry>
        <mesh
          filename="package://exhx5_description/meshes/right_link_6.STL" />
      </geometry>
      <material
        name="">
        <color
          rgba="0.79216 0.81961 0.93333 1" />
      </material>
    </visual>
    <collision>
      <origin
        xyz="0 0 0"
        rpy="0 0 0" />
      <geometry>
        <mesh
          filename="package://exhx5_description/meshes/right_link_6.STL" />
      </geometry>
    </collision>
  </link>
  <joint
    name="right_joint_6"
    type="revolute">
    <origin
      xyz="0.0465 0 0"
      rpy="-1.5708 0 0" />
    <parent
      link="right_link_5" />
    <child
      link="right_link_6" />
    <axis
      xyz="0 0 1" />
    <limit
      lower="-1.57"
      upper="1.57"
      effort="0"
      velocity="0" />
    <safety_controller
      k_velocity="0" />
  </joint>
  <link
    name="left_link_7">
    <inertial>
      <origin
        xyz="8.8124E-16 0.00049037 0.015811"
        rpy="0 0 0" />
      <mass
        value="0.017594" />
      <inertia
        ixx="8.0769E-06"
        ixy="1.4825E-21"
        ixz="-8.2707E-22"
        iyy="3.8081E-06"
        iyz="4.4924E-07"
        izz="6.9409E-06" />
    </inertial>
    <visual>
      <origin
        xyz="0 0 0"
        rpy="0 0 0" />
      <geometry>
        <mesh
          filename="package://exhx5_description/meshes/left_link_7.STL" />
      </geometry>
      <material
        name="">
        <color
          rgba="0.79216 0.81961 0.93333 1" />
      </material>
    </visual>
    <collision>
      <origin
        xyz="0 0 0"
        rpy="0 0 0" />
      <geometry>
        <mesh
          filename="package://exhx5_description/meshes/left_link_7.STL" />
      </geometry>
    </collision>
  </link>
  <joint
    name="left_joint_7"
    type="revolute">
    <origin
      xyz="0.005 0.054 0.1967"
      rpy="0 0 1.5708" />
    <parent
      link="base_link" />
    <child
      link="left_link_7" />
    <axis
      xyz="-2.8454E-05 0 1" />
    <limit
      lower="-1.57"
      upper="1.57"
      effort="0"
      velocity="0" />
    <safety_controller
      k_velocity="0" />
  </joint>
  <link
    name="left_link_8">
    <inertial>
      <origin
        xyz="0.013576 -0.00035038 -0.020028"
        rpy="0 0 0" />
      <mass
        value="0.098221" />
      <inertia
        ixx="1.7307E-05"
        ixy="-2.6908E-07"
        ixz="3.1908E-07"
        iyy="2.5083E-05"
        iyz="-1.1436E-12"
        izz="2.5141E-05" />
    </inertial>
    <visual>
      <origin
        xyz="0 0 0"
        rpy="0 0 0" />
      <geometry>
        <mesh
          filename="package://exhx5_description/meshes/left_link_8.STL" />
      </geometry>
      <material
        name="">
        <color
          rgba="0.79216 0.81961 0.93333 1" />
      </material>
    </visual>
    <collision>
      <origin
        xyz="0 0 0"
        rpy="0 0 0" />
      <geometry>
        <mesh
          filename="package://exhx5_description/meshes/left_link_8.STL" />
      </geometry>
    </collision>
  </link>
  <joint
    name="left_joint_8"
    type="revolute">
    <origin
      xyz="0 0 0"
      rpy="1.5708 1.5708 0" />
    <parent
      link="left_link_7" />
    <child
      link="left_link_8" />
    <axis
      xyz="0 0 1" />
    <limit
      lower="-1.57"
      upper="1.57"
      effort="0"
      velocity="0" />
    <safety_controller
      k_velocity="0" />
  </joint>
  <link
    name="left_link_9">
    <inertial>
      <origin
        xyz="0.041705 0.0061699 2.1325E-08"
        rpy="0 0 0" />
      <mass
        value="0.023646" />
      <inertia
        ixx="1.2406E-05"
        ixy="-7.7791E-07"
        ixz="8.1343E-13"
        iyy="2.2891E-05"
        iyz="4.6012E-12"
        izz="1.4533E-05" />
    </inertial>
    <visual>
      <origin
        xyz="0 0 0"
        rpy="0 0 0" />
      <geometry>
        <mesh
          filename="package://exhx5_description/meshes/left_link_9.STL" />
      </geometry>
      <material
        name="">
        <color
          rgba="0.79216 0.81961 0.93333 1" />
      </material>
    </visual>
    <collision>
      <origin
        xyz="0 0 0"
        rpy="0 0 0" />
      <geometry>
        <mesh
          filename="package://exhx5_description/meshes/left_link_9.STL" />
      </geometry>
    </collision>
  </link>
  <joint
    name="left_joint_9"
    type="revolute">
    <origin
      xyz="0 0 0"
      rpy="1.5708 0 0" />
    <parent
      link="left_link_8" />
    <child
      link="left_link_9" />
    <axis
      xyz="0 0 -1" />
    <limit
      lower="-1.57"
      upper="1.57"
      effort="0"
      velocity="0" />
    <safety_controller
      k_velocity="0" />
  </joint>
  <link
    name="left_link_10">
    <inertial>
      <origin
        xyz="0.025567 0.0092446 0.00043028"
        rpy="0 0 0" />
      <mass
        value="0.10219" />
      <inertia
        ixx="2.4767E-05"
        ixy="5.0737E-07"
        ixz="-1.2513E-07"
        iyy="2.3061E-05"
        iyz="3.2454E-07"
        izz="2.6112E-05" />
    </inertial>
    <visual>
      <origin
        xyz="0 0 0"
        rpy="0 0 0" />
      <geometry>
        <mesh
          filename="package://exhx5_description/meshes/left_link_10.STL" />
      </geometry>
      <material
        name="">
        <color
          rgba="0.79216 0.81961 0.93333 1" />
      </material>
    </visual>
    <collision>
      <origin
        xyz="0 0 0"
        rpy="0 0 0" />
      <geometry>
        <mesh
          filename="package://exhx5_description/meshes/left_link_10.STL" />
      </geometry>
    </collision>
  </link>
  <joint
    name="left_joint_10"
    type="revolute">
    <origin
      xyz="0.075954 0 0"
      rpy="0 0.0025296 0.42593" />
    <parent
      link="left_link_9" />
    <child
      link="left_link_10" />
    <axis
      xyz="0.0025296 0 -1" />
    <limit
      lower="-1.57"
      upper="1.57"
      effort="0"
      velocity="0" />
    <safety_controller
      k_velocity="0" />
  </joint>
  <link
    name="left_link_11">
    <inertial>
      <origin
        xyz="0.02325 2.3176E-15 -1.5266E-15"
        rpy="0 0 0" />
      <mass
        value="0.0095421" />
      <inertia
        ixx="3.5492E-06"
        ixy="-5.2205E-21"
        ixz="1.846E-21"
        iyy="2.8994E-06"
        iyz="-6.672E-22"
        izz="2.8994E-06" />
    </inertial>
    <visual>
      <origin
        xyz="0 0 0"
        rpy="0 0 0" />
      <geometry>
        <mesh
          filename="package://exhx5_description/meshes/left_link_11.STL" />
      </geometry>
      <material
        name="">
        <color
          rgba="0.79216 0.81961 0.93333 1" />
      </material>
    </visual>
    <collision>
      <origin
        xyz="0 0 0"
        rpy="0 0 0" />
      <geometry>
        <mesh
          filename="package://exhx5_description/meshes/left_link_11.STL" />
      </geometry>
    </collision>
  </link>
  <joint
    name="left_joint_11"
    type="revolute">
    <origin
      xyz="0.059298 0 0"
      rpy="0.0010451 -0.0023036 -0.42593" />
    <parent
      link="left_link_10" />
    <child
      link="left_link_11" />
    <axis
      xyz="0 0 1" />
    <limit
      lower="-1.57"
      upper="1.57"
      effort="0"
      velocity="0" />
    <safety_controller
      k_velocity="0" />
  </joint>
  <link
    name="left_link_12">
    <inertial>
      <origin
        xyz="0.007201 0.010484 0.01657"
        rpy="0 0 0" />
      <mass
        value="0.10557" />
      <inertia
        ixx="0.00010477"
        ixy="1.0972E-06"
        ixz="4.5956E-07"
        iyy="8.4496E-05"
        iyz="2.0811E-06"
        izz="3.2123E-05" />
    </inertial>
    <visual>
      <origin
        xyz="0 0 0"
        rpy="0 0 0" />
      <geometry>
        <mesh
          filename="package://exhx5_description/meshes/left_link_12.STL" />
      </geometry>
      <material
        name="">
        <color
          rgba="0.79216 0.81961 0.93333 1" />
      </material>
    </visual>
    <collision>
      <origin
        xyz="0 0 0"
        rpy="0 0 0" />
      <geometry>
        <mesh
          filename="package://exhx5_description/meshes/left_link_12.STL" />
      </geometry>
    </collision>
  </link>
  <joint
    name="left_joint_12"
    type="revolute">
    <origin
      xyz="0.0465 0 0"
      rpy="-1.5708 0 0" />
    <parent
      link="left_link_11" />
    <child
      link="left_link_12" />
    <axis
      xyz="0 0 1" />
    <limit
      lower="-1.57"
      upper="1.57"
      effort="0"
      velocity="0" />
    <safety_controller
      k_velocity="0" />
  </joint>
  <link
    name="head_link_13">
    <inertial>
      <origin
        xyz="0.023537 -0.003724 -0.00028487"
        rpy="0 0 0" />
      <mass
        value="0.1662" />
      <inertia
        ixx="6.6503E-05"
        ixy="1.0732E-06"
        ixz="6.9267E-06"
        iyy="0.00022623"
        iyz="4.8946E-06"
        izz="0.00025375" />
    </inertial>
    <visual>
      <origin
        xyz="0 0 0"
        rpy="0 0 0" />
      <geometry>
        <mesh
          filename="package://exhx5_description/meshes/head_link_13.STL" />
      </geometry>
      <material
        name="">
        <color
          rgba="0.79216 0.81961 0.93333 1" />
      </material>
    </visual>
    <collision>
      <origin
        xyz="0 0 0"
        rpy="0 0 0" />
      <geometry>
        <mesh
          filename="package://exhx5_description/meshes/head_link_13.STL" />
      </geometry>
    </collision>
  </link>
  <joint
    name="head_joint_13"
    type="revolute">
    <origin
      xyz="0.09365 0 0.32374"
      rpy="1.5708 -1.5708 0" />
    <parent
      link="base_link" />
    <child
      link="head_link_13" />
    <axis
      xyz="0 0 -1" />
    <limit
      lower="-1.57"
      upper="1.57"
      effort="0"
      velocity="0" />
    <safety_controller
      k_velocity="0" />
  </joint>
  <link
    name="head_link_14">
    <inertial>
      <origin
        xyz="0.00027149 0.013146 0.00070546"
        rpy="0 0 0" />
      <mass
        value="0.0061954" />
      <inertia
        ixx="4.6408E-07"
        ixy="1.3817E-08"
        ixz="3.8762E-09"
        iyy="5.8024E-07"
        iyz="1.5374E-08"
        izz="5.3428E-07" />
    </inertial>
    <visual>
      <origin
        xyz="0 0 0"
        rpy="0 0 0" />
      <geometry>
        <mesh
          filename="package://exhx5_description/meshes/head_link_14.STL" />
      </geometry>
      <material
        name="">
        <color
          rgba="0.7451 0.7451 0.7451 1" />
      </material>
    </visual>
    <collision>
      <origin
        xyz="0 0 0"
        rpy="0 0 0" />
      <geometry>
        <mesh
          filename="package://exhx5_description/meshes/head_link_14.STL" />
      </geometry>
    </collision>
  </link>
  <joint
    name="head_joint_14"
    type="revolute">
    <origin
      xyz="0.14528 0 0"
      rpy="0 -1.5708 -1.5708" />
    <parent
      link="head_link_13" />
    <child
      link="head_link_14" />
    <axis
      xyz="-1 0 0" />
    <limit
      lower="-1.57"
      upper="1.57"
      effort="0"
      velocity="0" />
    <safety_controller
      k_velocity="0" />
  </joint>
  <link
    name="head_link_15">
    <inertial>
      <origin
        xyz="0.0052568 -9.7868E-05 0.053166"
        rpy="0 0 0" />
      <mass
        value="0.039218" />
      <inertia
        ixx="2.6979E-05"
        ixy="-3.471E-09"
        ixz="-1.7411E-06"
        iyy="1.8556E-05"
        iyz="-6.4409E-08"
        izz="2.0489E-05" />
    </inertial>
    <visual>
      <origin
        xyz="0 0 0"
        rpy="0 0 0" />
      <geometry>
        <mesh
          filename="package://exhx5_description/meshes/head_link_15.STL" />
      </geometry>
      <material
        name="">
        <color
          rgba="0.75294 0.75294 0.75294 1" />
      </material>
    </visual>
    <collision>
      <origin
        xyz="0 0 0"
        rpy="0 0 0" />
      <geometry>
        <mesh
          filename="package://exhx5_description/meshes/head_link_15.STL" />
      </geometry>
    </collision>
  </link>
  <joint
    name="head_joint_15"
    type="revolute">
    <origin
      xyz="0 0 0"
      rpy="-1.5708 1.5708 0" />
    <parent
      link="head_link_14" />
    <child
      link="head_link_15" />
    <axis
      xyz="0 0 -1" />
    <limit
      lower="-1.57"
      upper="1.57"
      effort="0"
      velocity="0" />
    <safety_controller
      k_velocity="0" />
  </joint>
</robot>
