<?xml version="1.0" encoding="utf-8"?>
<!-- This URDF was automatically created by SolidWorks to URDF Exporter! Originally created by Stephen Brawner (brawner@gmail.com) 
     Commit Version: 1.5.0-0-g9aa0fdb  Build Version: 1.5.7004.21443
     For more information, please see http://wiki.ros.org/sw_urdf_exporter -->
<robot
  name="exhx5_w_b_4">
  <link
    name="body_link">
    <inertial>
      <origin
        xyz="-0.0042379 -3.8815E-05 0.082564"
        rpy="0 0 0" />
      <mass
        value="2.0289" />
      <inertia
        ixx="0.003028"
        ixy="-1.1548E-13"
        ixz="1.3914E-06"
        iyy="0.0012834"
        iyz="6.0069E-16"
        izz="0.0037416" />
    </inertial>
    <visual>
      <origin
        xyz="0 0 0"
        rpy="0 0 0" />
      <geometry>
        <mesh
          filename="package://exhx5_w_b_4/meshes/body_link.STL" />
      </geometry>
      <material
        name="">
        <color
          rgba="0.9451 1 0.18431 1" />
      </material>
    </visual>
    <collision>
      <origin
        xyz="0 0 0"
        rpy="0 0 0" />
      <geometry>
        <mesh
          filename="package://exhx5_w_b_4/meshes/body_link.STL" />
      </geometry>
    </collision>
  </link>

  <link
    name="r_hip_yaw_link">
    <inertial>
      <origin
        xyz="-8.7512E-08 -0.0043916 -0.011937"
        rpy="0 0 0" />
      <mass
        value="0.060374" />
      <inertia
        ixx="2.2334E-05"
        ixy="7.1418E-11"
        ixz="-2.5162E-11"
        iyy="1.1654E-05"
        iyz="-9.1442E-09"
        izz="2.4883E-05" />
    </inertial>
    <visual>
      <origin
        xyz="0 0 0"
        rpy="0 0 0" />
      <geometry>
        <mesh
          filename="package://exhx5_w_b_4/meshes/r_hip_yaw_link.STL" />
      </geometry>
      <material
        name="">
        <color
          rgba="0.9451 1 0.18431 1" />
      </material>
    </visual>
    <collision>
      <origin
        xyz="0 0 0"
        rpy="0 0 0" />
      <geometry>
        <mesh
          filename="package://exhx5_w_b_4/meshes/r_hip_yaw_link.STL" />
      </geometry>
    </collision>
  </link>
  <joint
    name="r_hip_yaw"
    type="revolute">
    <origin
      xyz="0 -0.045 0"
      rpy="-3.1416 0 1.5708" />
    <parent
      link="body_link" />
    <child
      link="r_hip_yaw_link" />
    <axis
      xyz="0 0 1" />
    <limit
      lower="-3.14"
      upper="3.14"
      effort="0"
      velocity="0" />
    <safety_controller
      k_velocity="0" />
  </joint>
  <link
    name="r_hip_roll_link">
    <inertial>
      <origin
        xyz="0.013831 0.00033457 0.025453"
        rpy="0 0 0" />
      <mass
        value="0.2969" />
      <inertia
        ixx="7.8136E-05"
        ixy="7.265E-07"
        ixz="-6.9809E-08"
        iyy="9.2183E-05"
        iyz="-5.6564E-11"
        izz="7.1034E-05" />
    </inertial>
    <visual>
      <origin
        xyz="0 0 0"
        rpy="0 0 0" />
      <geometry>
        <mesh
          filename="package://exhx5_w_b_4/meshes/r_hip_roll_link.STL" />
      </geometry>
      <material
        name="">
        <color
          rgba="0.9451 1 0.18431 1" />
      </material>
    </visual>
    <collision>
      <origin
        xyz="0 0 0"
        rpy="0 0 0" />
      <geometry>
        <mesh
          filename="package://exhx5_w_b_4/meshes/r_hip_roll_link.STL" />
      </geometry>
    </collision>
  </link>
  <joint
    name="r_hip_roll"
    type="revolute">
    <origin
      xyz="0 0 0"
      rpy="1.5708 -1.5708 0" />
    <parent
      link="r_hip_yaw_link" />
    <child
      link="r_hip_roll_link" />
    <axis
      xyz="0 0 1" />
    <limit
      lower="-3.14"
      upper="3.14"
      effort="0"
      velocity="0" />
    <safety_controller
      k_velocity="0" />
  </joint>
  <link
    name="r_hip_pitch_link">
    <inertial>
      <origin
        xyz="0.041225 0.007321 4.861E-08"
        rpy="0 0 0" />
      <mass
        value="0.051592" />
      <inertia
        ixx="2.7959E-05"
        ixy="-2.0752E-06"
        ixz="7.3863E-11"
        iyy="4.8156E-05"
        iyz="3.1562E-11"
        izz="2.9604E-05" />
    </inertial>
    <visual>
      <origin
        xyz="0 0 0"
        rpy="0 0 0" />
      <geometry>
        <mesh
          filename="package://exhx5_w_b_4/meshes/r_hip_pitch_link.STL" />
      </geometry>
      <material
        name="">
        <color
          rgba="0.89804 0.91765 0.92941 1" />
      </material>
    </visual>
    <collision>
      <origin
        xyz="0 0 0"
        rpy="0 0 0" />
      <geometry>
        <mesh
          filename="package://exhx5_w_b_4/meshes/r_hip_pitch_link.STL" />
      </geometry>
    </collision>
  </link>
  <joint
    name="r_hip_pitch"
    type="revolute">
    <origin
      xyz="0 0 0"
      rpy="-1.5708 0 0" />
    <parent
      link="r_hip_roll_link" />
    <child
      link="r_hip_pitch_link" />
    <axis
      xyz="0 0 1" />
    <limit
      lower="-3.14"
      upper="3.14"
      effort="0"
      velocity="0" />
    <safety_controller
      k_velocity="0" />
  </joint>
  <link
    name="r_knee_link">
    <inertial>
      <origin
        xyz="0.033756 0.0084189 7.0869E-09"
        rpy="0 0 0" />
      <mass
        value="0.28878" />
      <inertia
        ixx="6.6724E-05"
        ixy="-7.5004E-07"
        ixz="8.4578E-07"
        iyy="6.5699E-05"
        iyz="4.1085E-07"
        izz="7.0381E-05" />
    </inertial>
    <visual>
      <origin
        xyz="0 0 0"
        rpy="0 0 0" />
      <geometry>
        <mesh
          filename="package://exhx5_w_b_4/meshes/r_knee_link.STL" />
      </geometry>
      <material
        name="">
        <color
          rgba="0.9451 1 0.18431 1" />
      </material>
    </visual>
    <collision>
      <origin
        xyz="0 0 0"
        rpy="0 0 0" />
      <geometry>
        <mesh
          filename="package://exhx5_w_b_4/meshes/r_knee_link.STL" />
      </geometry>
    </collision>
  </link>
  <joint
    name="r_knee"
    type="revolute">
    <origin
      xyz="0.075954 0 0"
      rpy="0 0 0" />
    <parent
      link="r_hip_pitch_link" />
    <child
      link="r_knee_link" />
    <axis
      xyz="0 0 1" />
    <limit
      lower="-3.14"
      upper="3.14"
      effort="0"
      velocity="0" />
    <safety_controller
      k_velocity="0" />
  </joint>
  <link
    name="r_ank_pitch_link">
    <inertial>
      <origin
        xyz="0.022786 -8.5366E-09 -7.1994E-06"
        rpy="0 0 0" />
      <mass
        value="0.044772" />
      <inertia
        ixx="1.777E-05"
        ixy="-5.6509E-13"
        ixz="-3.3702E-09"
        iyy="1.7119E-05"
        iyz="1.8799E-11"
        izz="1.8661E-05" />
    </inertial>
    <visual>
      <origin
        xyz="0 0 0"
        rpy="0 0 0" />
      <geometry>
        <mesh
          filename="package://exhx5_w_b_4/meshes/r_ank_pitch_link.STL" />
      </geometry>
      <material
        name="">
        <color
          rgba="0.89804 0.91765 0.92941 1" />
      </material>
    </visual>
    <collision>
      <origin
        xyz="0 0 0"
        rpy="0 0 0" />
      <geometry>
        <mesh
          filename="package://exhx5_w_b_4/meshes/r_ank_pitch_link.STL" />
      </geometry>
    </collision>
  </link>
  <joint
    name="r_ank_pitch"
    type="revolute">
    <origin
      xyz="0.074602 0 0"
      rpy="3.1416 0 0" />
    <parent
      link="r_knee_link" />
    <child
      link="r_ank_pitch_link" />
    <axis
      xyz="0 0 1" />
    <limit
      lower="-3.14"
      upper="3.14"
      effort="0"
      velocity="0" />
    <safety_controller
      k_velocity="0" />
  </joint>
  <link
    name="r_ank_roll_link">
    <inertial>
      <origin
        xyz="0.0028428 -0.011717 0.011396"
        rpy="0 0 0" />
      <mass
        value="0.18479" />
      <inertia
        ixx="0.00019443"
        ixy="-2.4883E-06"
        ixz="1.1391E-06"
        iyy="0.0001398"
        iyz="-4.5796E-06"
        izz="7.2546E-05" />
    </inertial>
    <visual>
      <origin
        xyz="0 0 0"
        rpy="0 0 0" />
      <geometry>
        <mesh
          filename="package://exhx5_w_b_4/meshes/r_ank_roll_link.STL" />
      </geometry>
      <material
        name="">
        <color
          rgba="0.9451 1 0.18431 1" />
      </material>
    </visual>
    <collision>
      <origin
        xyz="0 0 0"
        rpy="0 0 0" />
      <geometry>
        <mesh
          filename="package://exhx5_w_b_4/meshes/r_ank_roll_link.STL" />
      </geometry>
    </collision>
  </link>
  <joint
    name="r_ank_roll"
    type="revolute">
    <origin
      xyz="0.0465 0 0"
      rpy="1.5708 0 0" />
    <parent
      link="r_ank_pitch_link" />
    <child
      link="r_ank_roll_link" />
    <axis
      xyz="0 0 1" />
    <limit
      lower="-3.14"
      upper="3.14"
      effort="0"
      velocity="0" />
    <safety_controller
      k_velocity="0" />
  </joint>
  <link
    name="l_hip_yaw_link">
    <inertial>
      <origin
        xyz="-8.7512E-08 -0.0043916 -0.011937"
        rpy="0 0 0" />
      <mass
        value="0.060374" />
      <inertia
        ixx="2.2334E-05"
        ixy="7.1418E-11"
        ixz="-2.5162E-11"
        iyy="1.1654E-05"
        iyz="-9.1442E-09"
        izz="2.4883E-05" />
    </inertial>
    <visual>
      <origin
        xyz="0 0 0"
        rpy="0 0 0" />
      <geometry>
        <mesh
          filename="package://exhx5_w_b_4/meshes/l_hip_yaw_link.STL" />
      </geometry>
      <material
        name="">
        <color
          rgba="0.9451 1 0.18431 1" />
      </material>
    </visual>
    <collision>
      <origin
        xyz="0 0 0"
        rpy="0 0 0" />
      <geometry>
        <mesh
          filename="package://exhx5_w_b_4/meshes/l_hip_yaw_link.STL" />
      </geometry>
    </collision>
  </link>
  <joint
    name="l_hip_yaw"
    type="revolute">
    <origin
      xyz="0 0.045 0"
      rpy="3.1416 0 1.5708" />
    <parent
      link="body_link" />
    <child
      link="l_hip_yaw_link" />
    <axis
      xyz="0 0 1" />
    <limit
      lower="-3.14"
      upper="3.14"
      effort="0"
      velocity="0" />
    <safety_controller
      k_velocity="0" />
  </joint>
  <link
    name="l_hip_roll_link">
    <inertial>
      <origin
        xyz="0.013831 0.00033457 0.025453"
        rpy="0 0 0" />
      <mass
        value="0.2969" />
      <inertia
        ixx="7.8136E-05"
        ixy="7.265E-07"
        ixz="-6.9809E-08"
        iyy="9.2183E-05"
        iyz="-5.6564E-11"
        izz="7.1034E-05" />
    </inertial>
    <visual>
      <origin
        xyz="0 0 0"
        rpy="0 0 0" />
      <geometry>
        <mesh
          filename="package://exhx5_w_b_4/meshes/l_hip_roll_link.STL" />
      </geometry>
      <material
        name="">
        <color
          rgba="0.9451 1 0.18431 1" />
      </material>
    </visual>
    <collision>
      <origin
        xyz="0 0 0"
        rpy="0 0 0" />
      <geometry>
        <mesh
          filename="package://exhx5_w_b_4/meshes/l_hip_roll_link.STL" />
      </geometry>
    </collision>
  </link>
  <joint
    name="l_hip_roll"
    type="revolute">
    <origin
      xyz="0 0 0"
      rpy="1.5708 -1.5708 0" />
    <parent
      link="l_hip_yaw_link" />
    <child
      link="l_hip_roll_link" />
    <axis
      xyz="0 0 1" />
    <limit
      lower="-3.14"
      upper="3.14"
      effort="0"
      velocity="0" />
    <safety_controller
      k_velocity="0" />
  </joint>
  <link
    name="l_hip_pitch_link">
    <inertial>
      <origin
        xyz="0.041225 -0.007321 -4.861E-08"
        rpy="0 0 0" />
      <mass
        value="0.051592" />
      <inertia
        ixx="2.7959E-05"
        ixy="2.0752E-06"
        ixz="-7.3863E-11"
        iyy="4.8156E-05"
        iyz="3.1562E-11"
        izz="2.9604E-05" />
    </inertial>
    <visual>
      <origin
        xyz="0 0 0"
        rpy="0 0 0" />
      <geometry>
        <mesh
          filename="package://exhx5_w_b_4/meshes/l_hip_pitch_link.STL" />
      </geometry>
      <material
        name="">
        <color
          rgba="0.89804 0.91765 0.92941 1" />
      </material>
    </visual>
    <collision>
      <origin
        xyz="0 0 0"
        rpy="0 0 0" />
      <geometry>
        <mesh
          filename="package://exhx5_w_b_4/meshes/l_hip_pitch_link.STL" />
      </geometry>
    </collision>
  </link>
  <joint
    name="l_hip_pitch"
    type="revolute">
    <origin
      xyz="0 0 0"
      rpy="1.5708 0 0" />
    <parent
      link="l_hip_roll_link" />
    <child
      link="l_hip_pitch_link" />
    <axis
      xyz="0 0 1" />
    <limit
      lower="-3.14"
      upper="3.14"
      effort="0"
      velocity="0" />
    <safety_controller
      k_velocity="0" />
  </joint>
  <link
    name="l_knee_link">
    <inertial>
      <origin
        xyz="0.033756 -0.0084189 -6.579E-09"
        rpy="0 0 0" />
      <mass
        value="0.28878" />
      <inertia
        ixx="6.6724E-05"
        ixy="7.5004E-07"
        ixz="-8.4578E-07"
        iyy="6.5699E-05"
        iyz="4.1085E-07"
        izz="7.0381E-05" />
    </inertial>
    <visual>
      <origin
        xyz="0 0 0"
        rpy="0 0 0" />
      <geometry>
        <mesh
          filename="package://exhx5_w_b_4/meshes/l_knee_link.STL" />
      </geometry>
      <material
        name="">
        <color
          rgba="0.9451 1 0.18431 1" />
      </material>
    </visual>
    <collision>
      <origin
        xyz="0 0 0"
        rpy="0 0 0" />
      <geometry>
        <mesh
          filename="package://exhx5_w_b_4/meshes/l_knee_link.STL" />
      </geometry>
    </collision>
  </link>
  <joint
    name="l_knee"
    type="revolute">
    <origin
      xyz="0.075954 0 0"
      rpy="0 0 0" />
    <parent
      link="l_hip_pitch_link" />
    <child
      link="l_knee_link" />
    <axis
      xyz="0 0 1" />
    <limit
      lower="-3.14"
      upper="3.14"
      effort="0"
      velocity="0" />
    <safety_controller
      k_velocity="0" />
  </joint>
  <link
    name="l_ank_pitch_link">
    <inertial>
      <origin
        xyz="0.022786 -1.0983E-08 -7.1997E-06"
        rpy="0 0 0" />
      <mass
        value="0.044772" />
      <inertia
        ixx="1.777E-05"
        ixy="8.4062E-13"
        ixz="-3.3729E-09"
        iyy="1.7119E-05"
        iyz="1.773E-11"
        izz="1.8661E-05" />
    </inertial>
    <visual>
      <origin
        xyz="0 0 0"
        rpy="0 0 0" />
      <geometry>
        <mesh
          filename="package://exhx5_w_b_4/meshes/l_ank_pitch_link.STL" />
      </geometry>
      <material
        name="">
        <color
          rgba="0.89804 0.91765 0.92941 1" />
      </material>
    </visual>
    <collision>
      <origin
        xyz="0 0 0"
        rpy="0 0 0" />
      <geometry>
        <mesh
          filename="package://exhx5_w_b_4/meshes/l_ank_pitch_link.STL" />
      </geometry>
    </collision>
  </link>
  <joint
    name="l_ank_pitch"
    type="revolute">
    <origin
      xyz="0.074602 0 0"
      rpy="3.1416 0 0" />
    <parent
      link="l_knee_link" />
    <child
      link="l_ank_pitch_link" />
    <axis
      xyz="0 0 1" />
    <limit
      lower="-3.14"
      upper="3.14"
      effort="0"
      velocity="0" />
    <safety_controller
      k_velocity="0" />
  </joint>
  <link
    name="l_ank_roll_link">
    <inertial>
      <origin
        xyz="0.0028732 0.011682 0.011547"
        rpy="0 0 0" />
      <mass
        value="0.18479" />
      <inertia
        ixx="0.00019911"
        ixy="2.7424E-06"
        ixz="1.1897E-06"
        iyy="0.00014332"
        iyz="4.7044E-06"
        izz="7.3992E-05" />
    </inertial>
    <visual>
      <origin
        xyz="0 0 0"
        rpy="0 0 0" />
      <geometry>
        <mesh
          filename="package://exhx5_w_b_4/meshes/l_ank_roll_link.STL" />
      </geometry>
      <material
        name="">
        <color
          rgba="0.9451 1 0.18431 1" />
      </material>
    </visual>
    <collision>
      <origin
        xyz="0 0 0"
        rpy="0 0 0" />
      <geometry>
        <mesh
          filename="package://exhx5_w_b_4/meshes/l_ank_roll_link.STL" />
      </geometry>
    </collision>
  </link>
  <joint
    name="l_ank_roll"
    type="revolute">
    <origin
      xyz="0.0465 0 0"
      rpy="-1.5708 0 0" />
    <parent
      link="l_ank_pitch_link" />
    <child
      link="l_ank_roll_link" />
    <axis
      xyz="0 0 1" />
    <limit
      lower="-3.14"
      upper="3.14"
      effort="0"
      velocity="0" />
    <safety_controller
      k_velocity="0" />
  </joint>
</robot>